Workbook

Sheet trades
A1: Инструмент | B1: Гос. рег. номер | C1: Тикер | D1: Номер сделки | E1: DateTime | F1: Кол-во | G1: Направление | H1: Валюта цены (номинала для облигаций) | I1: Цена сделки (% для облигаций) | J1: Валюта расчетов | K1: Объем сделки | L1: НКД по сделке в валюте расчетов | M1: Комиссия Брокера/Доп. комиссия Брокера "Сборы ТС"
A2: ОФЗ 26219, 26219RMFS, RU000A0JWM07 | C2: 26219RMFS | D2: 11047958427 | E2: 45517.432 | F2: 9 | G2: buy | H2: RUR | I2: 86.171 | J2: RUR | K2: 8036.28 | L2: 280.89 | M2: 2.99
A3: ОФЗ 26219, 26219RMFS, RU000A0JWM07 | C3: 26219RMFS | D3: 11048034579 | E3: 45517.433 | F3: 3 | G3: buy | H3: RUR | I3: 86.171 | J3: RUR | K3: 2678.76 | L3: 93.63 | M3: 1
A4: ОФЗ 26219, 26219RMFS, RU000A0JWM07 | C4: 26219RMFS | D4: 11048078982 | E4: 45517.438 | F4: 38 | G4: buy | H4: RUR | I4: 86.171 | J4: RUR | K4: 33930.96 | L4: 1185.98 | M4: 12.6
A5: ОФЗ 26219, 26219RMFS, RU000A0JWM07 | C5: 26219RMFS | D5: S11082834441 | E5: 45525.907 | F5: 50 | G5: sell | H5: RUR | I5: 85.688 | J5: RUR | K5: 44489.5 | L5: 1645.5 | M5: 16.49
A6: ОФЗ 26226, 26226RMFS, RU000A0ZZYW2 | C6: 26226RMFS | D6: 11049872636 | E6: 45517.529 | F6: 50 | G6: buy | H6: RUR | I6: 85.93 | J6: RUR | K6: 44337 | L6: 1372 | M6: 16.54
A7: ОФЗ 26226, 26226RMFS, RU000A0ZZYW2 | C7: 26226RMFS | D7: S11072031724 | E7: 45523.796 | F7: 4 | G7: sell | H7: RUR | I7: 85.441 | J7: RUR | K7: 3532.64 | L7: 115 | M7: 1.32
A8: ОФЗ 26226, 26226RMFS, RU000A0ZZYW2 | C8: 26226RMFS | D8: S11072037988 | E8: 45523.797 | F8: 1 | G8: sell | H8: RUR | I8: 85.441 | J8: RUR | K8: 883.16 | L8: 28.75 | M8: 0.33
A9: ОФЗ 26226, 26226RMFS, RU000A0ZZYW2 | C9: 26226RMFS | D9: S11072049843 | E9: 45523.798 | F9: 12 | G9: sell | H9: RUR | I9: 85.441 | J9: RUR | K9: 10597.92 | L9: 345 | M9: 3.95
A10: ОФЗ 26226, 26226RMFS, RU000A0ZZYW2 | C10: 26226RMFS | D10: S11072050728 | E10: 45523.799 | F10: 1 | G10: sell | H10: RUR | I10: 85.441 | J10: RUR | K10: 883.16 | L10: 28.75 | M10: 0.33
A11: ОФЗ 26226, 26226RMFS, RU000A0ZZYW2 | C11: 26226RMFS | D11: S11072053663 | E11: 45523.799 | F11: 18 | G11: sell | H11: RUR | I11: 85.441 | J11: RUR | K11: 15896.88 | L11: 517.5 | M11: 5.92
A12: ОФЗ 26226, 26226RMFS, RU000A0ZZYW2 | C12: 26226RMFS | D12: S11072088429 | E12: 45523.803 | F12: 5 | G12: sell | H12: RUR | I12: 85.441 | J12: RUR | K12: 4415.8 | L12: 143.75 | M12: 1.64
A13: ОФЗ 26226, 26226RMFS, RU000A0ZZYW2 | C13: 26226RMFS | D13: S11072106145 | E13: 45523.807 | F13: 1 | G13: sell | H13: RUR | I13: 85.441 | J13: RUR | K13: 883.16 | L13: 28.75 | M13: 0.33
A14: ОФЗ 26226, 26226RMFS, RU000A0ZZYW2 | C14: 26226RMFS | D14: S11072109875 | E14: 45523.808 | F14: 5 | G14: sell | H14: RUR | I14: 85.441 | J14: RUR | K14: 4415.8 | L14: 143.75 | M14: 1.64
A15: ОФЗ 26226, 26226RMFS, RU000A0ZZYW2 | C15: 26226RMFS | D15: S11072128090 | E15: 45523.811 | F15: 2 | G15: sell | H15: RUR | I15: 85.441 | J15: RUR | K15: 1766.32 | L15: 57.5 | M15: 0.65
A16: ОФЗ 26226, 26226RMFS, RU000A0ZZYW2 | C16: 26226RMFS | D16: S11072138721 | E16: 45523.812 | F16: 1 | G16: sell | H16: RUR | I16: 85.441 | J16: RUR | K16: 883.16 | L16: 28.75 | M16: 0.33
A17: ОФЗ 26229, 26229RMFS, RU000A100EG3 | C17: 26229RMFS | D17: 11048384635 | E17: 45517.449 | F17: 5 | G17: buy | H17: RUR | I17: 90.1 | J17: RUR | K17: 4594.15 | L17: 89.15 | M17: 1.73
A18: ОФЗ 26229, 26229RMFS, RU000A100EG3 | C18: 26229RMFS | D18: S11456710667 | E18: 45618.418 | F18: 5 | G18: sell | H18: RUR | I18: 88.792 | J18: RUR | K18: 4451.35 | L18: 11.75 | M18: 1.71
A19: ОФЗ 26234, 26234RMFS, RU000A101QE0 | C19: 26234RMFS | D19: 11047782481 | E19: 45517.424 | F19: 5 | G19: buy | H19: RUR | I19: 90.27 | J19: RUR | K19: 4530.75 | L19: 17.25 | M19: 1.73
A20: ОФЗ 26234, 26234RMFS, RU000A101QE0 | C20: 26234RMFS | D20: 11057781032 | E20: 45519.429 | F20: 1 | G20: buy | H20: RUR | I20: 90.21 | J20: RUR | K20: 905.8 | L20: 3.7 | M20: 0.34
A21: ОФЗ 26234, 26234RMFS, RU000A101QE0 | C21: 26234RMFS | D21: S11456701102 | E21: 45618.418 | F21: 5 | G21: sell | H21: RUR | I21: 90.814 | J21: RUR | K21: 4621.45 | L21: 80.75 | M21: 1.74
A22: ОФЗ 26234, 26234RMFS, RU000A101QE0 | C22: 26234RMFS | D22: S11456702175 | E22: 45618.418 | F22: 1 | G22: sell | H22: RUR | I22: 90.814 | J22: RUR | K22: 924.29 | L22: 16.15 | M22: 0.34
A23: Система ао | B23: 1-05-01669-A | C23: AFKS | D23: 2 | E23: 10.01.2022 17:07:21 | F23: 2500 | G23: buy | H23: RUB | I23: 23.694 | J23: RUB | K23: 59235 | M23: 11.85
A24: Система ао | B24: 1-05-01669-A | C24: AFKS | D24: 4844103702 | E24: 10.01.2022 17:07:21 | F24: 1000 | G24: buy | H24: RUB | I24: 23.694 | J24: RUB | K24: 23694 | M24: 11.85
A25: Система ао | B25: 1-05-01669-A | C25: AFKS | D25: 4868643995 | E25: 14.01.2022 16:17:44 | F25: 1000 | G25: buy | H25: RUB | I25: 21.767 | J25: RUB | K25: 21767 | M25: 10.88
A26: Система ао | B26: 1-05-01669-A | C26: AFKS | D26: 4892001079 | E26: 20.01.2022 15:34:19 | F26: 1000 | G26: buy | H26: RUB | I26: 21.74 | J26: RUB | K26: 21740 | M26: 10.87
A27: Система ао | B27: 1-05-01669-A | C27: AFKS | D27: 4895618957 | E27: 21.01.2022 07:05:20 | F27: 1000 | G27: buy | H27: RUB | I27: 21.7 | J27: RUB | K27: 21700 | M27: 10.85
A28: Система ао | B28: 1-05-01669-A | C28: AFKS | D28: 4902431110 | E28: 24.01.2022 11:21:13 | F28: 1000 | G28: buy | H28: RUB | I28: 20.44 | J28: RUB | K28: 20440 | M28: 10.22
A29: Система ао | B29: 1-05-01669-A | C29: AFKS | D29: 4903670881 | E29: 24.01.2022 13:24:13 | F29: 1000 | G29: buy | H29: RUB | I29: 19.717 | J29: RUB | K29: 19717 | M29: 9.86
A30: Система ао | B30: 1-05-01669-A | C30: AFKS | D30: 5002571899 | E30: 17.02.2022 12:36:32 | F30: 300 | G30: buy | H30: RUB | I30: 20.151 | J30: RUB | K30: 6045.3 | M30: 3.02
A31: Система ао | B31: 1-05-01669-A | C31: AFKS | D31: 5002572433 | E31: 17.02.2022 12:36:39 | F31: 4700 | G31: buy | H31: RUB | I31: 20.151 | J31: RUB | K31: 94709.7 | M31: 47.35
A32: Система ао | B32: 1-05-01669-A | C32: AFKS | D32: 5002756926 | E32: 17.02.2022 13:23:15 | F32: 1800 | G32: buy | H32: RUB | I32: 20.451 | J32: RUB | K32: 36811.8 | M32: 18.41
A33: Система ао | B33: 1-05-01669-A | C33: AFKS | D33: 5002783937 | E33: 17.02.2022 13:29:47 | F33: 1500 | G33: buy | H33: RUB | I33: 20.374 | J33: RUB | K33: 30561 | M33: 15.28
A34: Система ао | B34: 1-05-01669-A | C34: AFKS | D34: 5002932425 | E34: 17.02.2022 14:02:53 | F34: 100 | G34: buy | H34: RUB | I34: 20.481 | J34: RUB | K34: 2048.1 | M34: 1.02
... A58: Система ао | B58: 1-05-01669-A | C58: AFKS | D58: 5003692350 | E58: 17.02.2022 16:38:12 | F58: 100 | G58: sell | H58: RUB | I58: 19.983 | J58: RUB | K58: 1998.3 | M58: 1
A59: Система ао | B59: 1-05-01669-A | C59: =VLOOKUP(A59,[1]Лист2!A:B,2,0) -> AFKS | D59: 7583738440 | E59: 26.04.2023 12:11:23 | F59: 400 | G59: sell | H59: RUB | I59: 15.895 | J59: RUB | K59: 6358 | M59: 3.82
A60: Система ао | B60: 1-05-01669-A | C60: =VLOOKUP(A60,[1]Лист2!A:B,2,0) -> AFKS | D60: 7589470229 | E60: 28.04.2023 10:03:25 | F60: 400 | G60: sell | H60: RUB | I60: 15.96 | J60: RUB | K60: 6384 | M60: 1.92
A61: Система ао | B61: 1-05-01669-A | C61: =VLOOKUP(A61,[1]Лист2!A:B,2,0) -> AFKS | D61: 7611939741 | E61: 03.05.2023 15:30:44 | F61: 400 | G61: sell | H61: RUB | I61: 16.012 | J61: RUB | K61: 6404.8 | M61: 1.92
A62: Система ао | B62: 1-05-01669-A | C62: =VLOOKUP(A62,[1]Лист2!A:B,2,0) -> AFKS | D62: 7684859120 | E62: 25.05.2023 13:39:50 | F62: 5000 | G62: sell | H62: RUB | I62: 15.715 | J62: RUB | K62: 78575 | M62: 23.57
A63: Система ао | B63: 1-05-01669-A | C63: =VLOOKUP(A63,[1]Лист2!A:B,2,0) -> AFKS | D63: 7685502884 | E63: 25.05.2023 15:37:19 | F63: 2000 | G63: sell | H63: RUB | I63: 15.769 | J63: RUB | K63: 31538 | M63: 9.46
...
